time 0ms: Simulator started for FCFS [Q <empty>]
time 0ms: Process A arrived and added to ready queue [Q A]
time 0ms: Process B arrived and added to ready queue [Q A B]
time 0ms: Process C arrived and added to ready queue [Q A B C]
time 0ms: Process X arrived and added to ready queue [Q A B C X]
time 0ms: Process Y arrived and added to ready queue [Q A B C X Y]
time 0ms: Process Z arrived and added to ready queue [Q A B C X Y Z]
time 3ms: Process A started using the CPU [Q B C X Y Z]
time 103ms: Process A completed a CPU burst; 4 bursts to go [Q B C X Y Z]
time 103ms: Process A switching out of CPU; will block on I/O until time 306ms [Q B C X Y Z]
time 109ms: Process B started using the CPU [Q C X Y Z]
time 210ms: Process B completed a CPU burst; 4 bursts to go [Q C X Y Z]
time 210ms: Process B switching out of CPU; will block on I/O until time 413ms [Q C X Y Z]
time 216ms: Process C started using the CPU [Q X Y Z]
time 306ms: Process A completed I/O; added to ready queue [Q X Y Z A]
time 318ms: Process C completed a CPU burst; 4 bursts to go [Q X Y Z A]
time 318ms: Process C switching out of CPU; will block on I/O until time 521ms [Q X Y Z A]
time 324ms: Process X started using the CPU [Q Y Z A]
time 413ms: Process B completed I/O; added to ready queue [Q Y Z A B]
time 427ms: Process X completed a CPU burst; 4 bursts to go [Q Y Z A B]
time 427ms: Process X switching out of CPU; will block on I/O until time 630ms [Q Y Z A B]
time 433ms: Process Y started using the CPU [Q Z A B]
time 521ms: Process C completed I/O; added to ready queue [Q Z A B C]
time 537ms: Process Y completed a CPU burst; 4 bursts to go [Q Z A B C]
time 537ms: Process Y switching out of CPU; will block on I/O until time 740ms [Q Z A B C]
time 543ms: Process Z started using the CPU [Q A B C]
time 630ms: Process X completed I/O; added to ready queue [Q A B C X]
time 648ms: Process Z completed a CPU burst; 4 bursts to go [Q A B C X]
time 648ms: Process Z switching out of CPU; will block on I/O until time 851ms [Q A B C X]
time 654ms: Process A started using the CPU [Q B C X]
time 740ms: Process Y completed I/O; added to ready queue [Q B C X Y]
time 754ms: Process A completed a CPU burst; 3 bursts to go [Q B C X Y]
time 754ms: Process A switching out of CPU; will block on I/O until time 957ms [Q B C X Y]
time 760ms: Process B started using the CPU [Q C X Y]
time 851ms: Process Z completed I/O; added to ready queue [Q C X Y Z]
time 861ms: Process B completed a CPU burst; 3 bursts to go [Q C X Y Z]
time 861ms: Process B switching out of CPU; will block on I/O until time 1064ms [Q C X Y Z]
time 867ms: Process C started using the CPU [Q X Y Z]
time 957ms: Process A completed I/O; added to ready queue [Q X Y Z A]
time 969ms: Process C completed a CPU burst; 3 bursts to go [Q X Y Z A]
time 969ms: Process C switching out of CPU; will block on I/O until time 1172ms [Q X Y Z A]
time 975ms: Process X started using the CPU [Q Y Z A]
time 1064ms: Process B completed I/O; added to ready queue [Q Y Z A B]
time 1078ms: Process X completed a CPU burst; 3 bursts to go [Q Y Z A B]
time 1078ms: Process X switching out of CPU; will block on I/O until time 1281ms [Q Y Z A B]
time 1084ms: Process Y started using the CPU [Q Z A B]
time 1172ms: Process C completed I/O; added to ready queue [Q Z A B C]
time 1188ms: Process Y completed a CPU burst; 3 bursts to go [Q Z A B C]
time 1188ms: Process Y switching out of CPU; will block on I/O until time 1391ms [Q Z A B C]
time 1194ms: Process Z started using the CPU [Q A B C]
time 1281ms: Process X completed I/O; added to ready queue [Q A B C X]
time 1299ms: Process Z completed a CPU burst; 3 bursts to go [Q A B C X]
time 1299ms: Process Z switching out of CPU; will block on I/O until time 1502ms [Q A B C X]
time 1305ms: Process A started using the CPU [Q B C X]
time 1391ms: Process Y completed I/O; added to ready queue [Q B C X Y]
time 1405ms: Process A completed a CPU burst; 2 bursts to go [Q B C X Y]
time 1405ms: Process A switching out of CPU; will block on I/O until time 1608ms [Q B C X Y]
time 1411ms: Process B started using the CPU [Q C X Y]
time 1502ms: Process Z completed I/O; added to ready queue [Q C X Y Z]
time 1512ms: Process B completed a CPU burst; 2 bursts to go [Q C X Y Z]
time 1512ms: Process B switching out of CPU; will block on I/O until time 1715ms [Q C X Y Z]
time 1518ms: Process C started using the CPU [Q X Y Z]
time 1608ms: Process A completed I/O; added to ready queue [Q X Y Z A]
time 1620ms: Process C completed a CPU burst; 2 bursts to go [Q X Y Z A]
time 1620ms: Process C switching out of CPU; will block on I/O until time 1823ms [Q X Y Z A]
time 1626ms: Process X started using the CPU [Q Y Z A]
time 1715ms: Process B completed I/O; added to ready queue [Q Y Z A B]
time 1729ms: Process X completed a CPU burst; 2 bursts to go [Q Y Z A B]
time 1729ms: Process X switching out of CPU; will block on I/O until time 1932ms [Q Y Z A B]
time 1735ms: Process Y started using the CPU [Q Z A B]
time 1823ms: Process C completed I/O; added to ready queue [Q Z A B C]
time 1839ms: Process Y completed a CPU burst; 2 bursts to go [Q Z A B C]
time 1839ms: Process Y switching out of CPU; will block on I/O until time 2042ms [Q Z A B C]
time 1845ms: Process Z started using the CPU [Q A B C]
time 1932ms: Process X completed I/O; added to ready queue [Q A B C X]
time 1950ms: Process Z completed a CPU burst; 2 bursts to go [Q A B C X]
time 1950ms: Process Z switching out of CPU; will block on I/O until time 2153ms [Q A B C X]
time 1956ms: Process A started using the CPU [Q B C X]
time 2042ms: Process Y completed I/O; added to ready queue [Q B C X Y]
time 2056ms: Process A completed a CPU burst; 1 burst to go [Q B C X Y]
time 2056ms: Process A switching out of CPU; will block on I/O until time 2259ms [Q B C X Y]
time 2062ms: Process B started using the CPU [Q C X Y]
time 2153ms: Process Z completed I/O; added to ready queue [Q C X Y Z]
time 2163ms: Process B completed a CPU burst; 1 burst to go [Q C X Y Z]
time 2163ms: Process B switching out of CPU; will block on I/O until time 2366ms [Q C X Y Z]
time 2169ms: Process C started using the CPU [Q X Y Z]
time 2259ms: Process A completed I/O; added to ready queue [Q X Y Z A]
time 2271ms: Process C completed a CPU burst; 1 burst to go [Q X Y Z A]
time 2271ms: Process C switching out of CPU; will block on I/O until time 2474ms [Q X Y Z A]
time 2277ms: Process X started using the CPU [Q Y Z A]
time 2366ms: Process B completed I/O; added to ready queue [Q Y Z A B]
time 2380ms: Process X completed a CPU burst; 1 burst to go [Q Y Z A B]
time 2380ms: Process X switching out of CPU; will block on I/O until time 2583ms [Q Y Z A B]
time 2386ms: Process Y started using the CPU [Q Z A B]
time 2474ms: Process C completed I/O; added to ready queue [Q Z A B C]
time 2490ms: Process Y completed a CPU burst; 1 burst to go [Q Z A B C]
time 2490ms: Process Y switching out of CPU; will block on I/O until time 2693ms [Q Z A B C]
time 2496ms: Process Z started using the CPU [Q A B C]
time 2583ms: Process X completed I/O; added to ready queue [Q A B C X]
time 2601ms: Process Z completed a CPU burst; 1 burst to go [Q A B C X]
time 2601ms: Process Z switching out of CPU; will block on I/O until time 2804ms [Q A B C X]
time 2607ms: Process A started using the CPU [Q B C X]
time 2693ms: Process Y completed I/O; added to ready queue [Q B C X Y]
time 2707ms: Process A terminated [Q B C X Y]
time 2713ms: Process B started using the CPU [Q C X Y]
time 2804ms: Process Z completed I/O; added to ready queue [Q C X Y Z]
time 2814ms: Process B terminated [Q C X Y Z]
time 2820ms: Process C started using the CPU [Q X Y Z]
time 2922ms: Process C terminated [Q X Y Z]
time 2928ms: Process X started using the CPU [Q Y Z]
time 3031ms: Process X terminated [Q Y Z]
time 3037ms: Process Y started using the CPU [Q Z]
time 3141ms: Process Y terminated [Q Z]
time 3147ms: Process Z started using the CPU [Q <empty>]
time 3252ms: Process Z terminated [Q <empty>]
time 3255ms: Simulator ended for FCFS

time 0ms: Simulator started for SRT [Q <empty>]
time 0ms: Process A arrived and added to ready queue [Q A]
time 0ms: Process B arrived and added to ready queue [Q A B]
time 0ms: Process C arrived and added to ready queue [Q A B C]
time 0ms: Process X arrived and added to ready queue [Q A B C X]
time 0ms: Process Y arrived and added to ready queue [Q A B C X Y]
time 0ms: Process Z arrived and added to ready queue [Q A B C X Y Z]
time 3ms: Process A started using the CPU [Q B C X Y Z]
time 103ms: Process A completed a CPU burst; 4 bursts to go [Q B C X Y Z]
time 103ms: Process A switching out of CPU; will block on I/O until time 306ms [Q B C X Y Z]
time 109ms: Process B started using the CPU [Q C X Y Z]
time 210ms: Process B completed a CPU burst; 4 bursts to go [Q C X Y Z]
time 210ms: Process B switching out of CPU; will block on I/O until time 413ms [Q C X Y Z]
time 216ms: Process C started using the CPU [Q X Y Z]
time 306ms: Process A completed I/O; added to ready queue [Q A X Y Z]
time 318ms: Process C completed a CPU burst; 4 bursts to go [Q A X Y Z]
time 318ms: Process C switching out of CPU; will block on I/O until time 521ms [Q A X Y Z]
time 324ms: Process A started using the CPU [Q X Y Z]
time 413ms: Process B completed I/O; added to ready queue [Q B X Y Z]
time 424ms: Process A completed a CPU burst; 3 bursts to go [Q B X Y Z]
time 424ms: Process A switching out of CPU; will block on I/O until time 627ms [Q B X Y Z]
time 430ms: Process B started using the CPU [Q X Y Z]
time 521ms: Process C completed I/O; added to ready queue [Q C X Y Z]
time 531ms: Process B completed a CPU burst; 3 bursts to go [Q C X Y Z]
time 531ms: Process B switching out of CPU; will block on I/O until time 734ms [Q C X Y Z]
time 537ms: Process C started using the CPU [Q X Y Z]
time 627ms: Process A completed I/O; added to ready queue [Q A X Y Z]
time 639ms: Process C completed a CPU burst; 3 bursts to go [Q A X Y Z]
time 639ms: Process C switching out of CPU; will block on I/O until time 842ms [Q A X Y Z]
time 645ms: Process A started using the CPU [Q X Y Z]
time 734ms: Process B completed I/O; added to ready queue [Q B X Y Z]
time 745ms: Process A completed a CPU burst; 2 bursts to go [Q B X Y Z]
time 745ms: Process A switching out of CPU; will block on I/O until time 948ms [Q B X Y Z]
time 751ms: Process B started using the CPU [Q X Y Z]
time 842ms: Process C completed I/O; added to ready queue [Q C X Y Z]
time 852ms: Process B completed a CPU burst; 2 bursts to go [Q C X Y Z]
time 852ms: Process B switching out of CPU; will block on I/O until time 1055ms [Q C X Y Z]
time 858ms: Process C started using the CPU [Q X Y Z]
time 948ms: Process A completed I/O; added to ready queue [Q A X Y Z]
time 960ms: Process C completed a CPU burst; 2 bursts to go [Q A X Y Z]
time 960ms: Process C switching out of CPU; will block on I/O until time 1163ms [Q A X Y Z]
time 966ms: Process A started using the CPU [Q X Y Z]
time 1055ms: Process B completed I/O; added to ready queue [Q B X Y Z]
time 1066ms: Process A completed a CPU burst; 1 burst to go [Q B X Y Z]
time 1066ms: Process A switching out of CPU; will block on I/O until time 1269ms [Q B X Y Z]
time 1072ms: Process B started using the CPU [Q X Y Z]
time 1163ms: Process C completed I/O; added to ready queue [Q C X Y Z]
time 1173ms: Process B completed a CPU burst; 1 burst to go [Q C X Y Z]
time 1173ms: Process B switching out of CPU; will block on I/O until time 1376ms [Q C X Y Z]
time 1179ms: Process C started using the CPU [Q X Y Z]
time 1269ms: Process A completed I/O; added to ready queue [Q A X Y Z]
time 1281ms: Process C completed a CPU burst; 1 burst to go [Q A X Y Z]
time 1281ms: Process C switching out of CPU; will block on I/O until time 1484ms [Q A X Y Z]
time 1287ms: Process A started using the CPU [Q X Y Z]
time 1376ms: Process B completed I/O; added to ready queue [Q B X Y Z]
time 1387ms: Process A terminated [Q B X Y Z]
time 1393ms: Process B started using the CPU [Q X Y Z]
time 1484ms: Process C completed I/O; added to ready queue [Q C X Y Z]
time 1494ms: Process B terminated [Q C X Y Z]
time 1500ms: Process C started using the CPU [Q X Y Z]
time 1602ms: Process C terminated [Q X Y Z]
time 1608ms: Process X started using the CPU [Q Y Z]
time 1711ms: Process X completed a CPU burst; 4 bursts to go [Q Y Z]
time 1711ms: Process X switching out of CPU; will block on I/O until time 1914ms [Q Y Z]
time 1717ms: Process Y started using the CPU [Q Z]
time 1821ms: Process Y completed a CPU burst; 4 bursts to go [Q Z]
time 1821ms: Process Y switching out of CPU; will block on I/O until time 2024ms [Q Z]
time 1827ms: Process Z started using the CPU [Q <empty>]
time 1914ms: Process X completed I/O; added to ready queue [Q X]
time 1932ms: Process Z completed a CPU burst; 4 bursts to go [Q X]
time 1932ms: Process Z switching out of CPU; will block on I/O until time 2135ms [Q X]
time 1938ms: Process X started using the CPU [Q <empty>]
time 2024ms: Process Y completed I/O; added to ready queue [Q Y]
time 2041ms: Process X completed a CPU burst; 3 bursts to go [Q Y]
time 2041ms: Process X switching out of CPU; will block on I/O until time 2244ms [Q Y]
time 2047ms: Process Y started using the CPU [Q <empty>]
time 2135ms: Process Z completed I/O; added to ready queue [Q Z]
time 2151ms: Process Y completed a CPU burst; 3 bursts to go [Q Z]
time 2151ms: Process Y switching out of CPU; will block on I/O until time 2354ms [Q Z]
time 2157ms: Process Z started using the CPU [Q <empty>]
time 2244ms: Process X completed I/O; added to ready queue [Q X]
time 2262ms: Process Z completed a CPU burst; 3 bursts to go [Q X]
time 2262ms: Process Z switching out of CPU; will block on I/O until time 2465ms [Q X]
time 2268ms: Process X started using the CPU [Q <empty>]
time 2354ms: Process Y completed I/O; added to ready queue [Q Y]
time 2371ms: Process X completed a CPU burst; 2 bursts to go [Q Y]
time 2371ms: Process X switching out of CPU; will block on I/O until time 2574ms [Q Y]
time 2377ms: Process Y started using the CPU [Q <empty>]
time 2465ms: Process Z completed I/O; added to ready queue [Q Z]
time 2481ms: Process Y completed a CPU burst; 2 bursts to go [Q Z]
time 2481ms: Process Y switching out of CPU; will block on I/O until time 2684ms [Q Z]
time 2487ms: Process Z started using the CPU [Q <empty>]
time 2574ms: Process X completed I/O; added to ready queue [Q X]
time 2592ms: Process Z completed a CPU burst; 2 bursts to go [Q X]
time 2592ms: Process Z switching out of CPU; will block on I/O until time 2795ms [Q X]
time 2598ms: Process X started using the CPU [Q <empty>]
time 2684ms: Process Y completed I/O; added to ready queue [Q Y]
time 2701ms: Process X completed a CPU burst; 1 burst to go [Q Y]
time 2701ms: Process X switching out of CPU; will block on I/O until time 2904ms [Q Y]
time 2707ms: Process Y started using the CPU [Q <empty>]
time 2795ms: Process Z completed I/O; added to ready queue [Q Z]
time 2811ms: Process Y completed a CPU burst; 1 burst to go [Q Z]
time 2811ms: Process Y switching out of CPU; will block on I/O until time 3014ms [Q Z]
time 2817ms: Process Z started using the CPU [Q <empty>]
time 2904ms: Process X completed I/O; added to ready queue [Q X]
time 2922ms: Process Z completed a CPU burst; 1 burst to go [Q X]
time 2922ms: Process Z switching out of CPU; will block on I/O until time 3125ms [Q X]
time 2928ms: Process X started using the CPU [Q <empty>]
time 3014ms: Process Y completed I/O; added to ready queue [Q Y]
time 3031ms: Process X terminated [Q Y]
time 3037ms: Process Y started using the CPU [Q <empty>]
time 3125ms: Process Z completed I/O; added to ready queue [Q Z]
time 3141ms: Process Y terminated [Q Z]
time 3147ms: Process Z started using the CPU [Q <empty>]
time 3252ms: Process Z terminated [Q <empty>]
time 3255ms: Simulator ended for SRT

time 0ms: Simulator started for RR [Q <empty>]
time 0ms: Process A arrived and added to ready queue [Q A]
time 0ms: Process B arrived and added to ready queue [Q A B]
time 0ms: Process C arrived and added to ready queue [Q A B C]
time 0ms: Process X arrived and added to ready queue [Q A B C X]
time 0ms: Process Y arrived and added to ready queue [Q A B C X Y]
time 0ms: Process Z arrived and added to ready queue [Q A B C X Y Z]
time 3ms: Process A started using the CPU [Q B C X Y Z]
time 97ms: Time slice expired; process A preempted with 6ms to go [Q B C X Y Z]
time 103ms: Process B started using the CPU [Q C X Y Z A]
time 197ms: Time slice expired; process B preempted with 7ms to go [Q C X Y Z A]
time 203ms: Process C started using the CPU [Q X Y Z A B]
time 297ms: Time slice expired; process C preempted with 8ms to go [Q X Y Z A B]
time 300ms: Process A completed I/O; added to ready queue [Q X Y Z A B C A]
time 303ms: Process X started using the CPU [Q Y Z A B C A]
time 397ms: Time slice expired; process X preempted with 9ms to go [Q Y Z A B C A]
time 400ms: Process B completed I/O; added to ready queue [Q Y Z A B C A X B]
time 403ms: Process Y started using the CPU [Q Z A B C A X B]
time 497ms: Time slice expired; process Y preempted with 10ms to go [Q Z A B C A X B]
time 500ms: Process C completed I/O; added to ready queue [Q Z A B C A X B Y C]
time 503ms: Process Z started using the CPU [Q A B C A X B Y C]
time 597ms: Time slice expired; process Z preempted with 11ms to go [Q A B C A X B Y C]
time 600ms: Process X completed I/O; added to ready queue [Q A B C A X B Y C Z X]
time 603ms: Process A started using the CPU with 6ms remaining [Q B C A X B Y C Z X]
time 609ms: Process A completed a CPU burst; 4 bursts to go [Q B C A X B Y C Z X]
time 609ms: Process A switching out of CPU; will block on I/O until time 812ms [Q B C A X B Y C Z X]
time 615ms: Process B started using the CPU with 7ms remaining [Q C A X B Y C Z X]
time 622ms: Process B completed a CPU burst; 4 bursts to go [Q C A X B Y C Z X]
time 622ms: Process B switching out of CPU; will block on I/O until time 825ms [Q C A X B Y C Z X]
time 628ms: Process C started using the CPU with 8ms remaining [Q A X B Y C Z X]
time 636ms: Process C completed a CPU burst; 4 bursts to go [Q A X B Y C Z X]
time 636ms: Process C switching out of CPU; will block on I/O until time 839ms [Q A X B Y C Z X]
time 642ms: Process A started using the CPU with 6ms remaining [Q X B Y C Z X]
time 648ms: Process A completed a CPU burst; 4 bursts to go [Q X B Y C Z X]
time 648ms: Process A switching out of CPU; will block on I/O until time 851ms [Q X B Y C Z X]
time 654ms: Process X started using the CPU with 9ms remaining [Q B Y C Z X]
time 663ms: Process X completed a CPU burst; 4 bursts to go [Q B Y C Z X]
time 663ms: Process X switching out of CPU; will block on I/O until time 866ms [Q B Y C Z X]
time 669ms: Process B started using the CPU with 7ms remaining [Q Y C Z X]
time 676ms: Process B completed a CPU burst; 4 bursts to go [Q Y C Z X]
time 676ms: Process B switching out of CPU; will block on I/O until time 879ms [Q Y C Z X]
time 682ms: Process Y started using the CPU with 10ms remaining [Q C Z X]
time 692ms: Process Y completed a CPU burst; 4 bursts to go [Q C Z X]
time 692ms: Process Y switching out of CPU; will block on I/O until time 895ms [Q C Z X]
time 698ms: Process C started using the CPU with 8ms remaining [Q Z X]
time 706ms: Process C completed a CPU burst; 4 bursts to go [Q Z X]
time 706ms: Process C switching out of CPU; will block on I/O until time 909ms [Q Z X]
time 712ms: Process Z started using the CPU with 11ms remaining [Q X]
time 723ms: Process Z completed a CPU burst; 4 bursts to go [Q X]
time 723ms: Process Z switching out of CPU; will block on I/O until time 926ms [Q X]
time 729ms: Process X started using the CPU with 9ms remaining [Q <empty>]
time 738ms: Process X completed a CPU burst; 4 bursts to go [Q <empty>]
time 738ms: Process X switching out of CPU; will block on I/O until time 941ms [Q <empty>]
time 851ms: Process A completed I/O; added to ready queue [Q A]
time 854ms: Process A started using the CPU [Q <empty>]
time 879ms: Process B completed I/O; added to ready queue [Q B]
time 895ms: Process Y completed I/O; added to ready queue [Q B Y]
time 909ms: Process C completed I/O; added to ready queue [Q B Y C]
time 926ms: Process Z completed I/O; added to ready queue [Q B Y C Z]
time 941ms: Process X completed I/O; added to ready queue [Q B Y C Z X]
time 948ms: Time slice expired; process A preempted with 6ms to go [Q B Y C Z X]
time 954ms: Process B started using the CPU [Q Y C Z X A]
time 1048ms: Time slice expired; process B preempted with 7ms to go [Q Y C Z X A]
time 1054ms: Process Y started using the CPU [Q C Z X A B]
time 1148ms: Time slice expired; process Y preempted with 10ms to go [Q C Z X A B]
time 1151ms: Process A completed I/O; added to ready queue [Q C Z X A B Y A]
time 1154ms: Process C started using the CPU [Q Z X A B Y A]
time 1248ms: Time slice expired; process C preempted with 8ms to go [Q Z X A B Y A]
time 1251ms: Process B completed I/O; added to ready queue [Q Z X A B Y A C B]
time 1254ms: Process Z started using the CPU [Q X A B Y A C B]
time 1348ms: Time slice expired; process Z preempted with 11ms to go [Q X A B Y A C B]
time 1351ms: Process Y completed I/O; added to ready queue [Q X A B Y A C B Z Y]
time 1354ms: Process X started using the CPU [Q A B Y A C B Z Y]
time 1448ms: Time slice expired; process X preempted with 9ms to go [Q A B Y A C B Z Y]
time 1451ms: Process C completed I/O; added to ready queue [Q A B Y A C B Z Y X C]
time 1454ms: Process A started using the CPU with 6ms remaining [Q B Y A C B Z Y X C]
time 1460ms: Process A completed a CPU burst; 3 bursts to go [Q B Y A C B Z Y X C]
time 1460ms: Process A switching out of CPU; will block on I/O until time 1663ms [Q B Y A C B Z Y X C]
time 1466ms: Process B started using the CPU with 7ms remaining [Q Y A C B Z Y X C]
time 1473ms: Process B completed a CPU burst; 3 bursts to go [Q Y A C B Z Y X C]
time 1473ms: Process B switching out of CPU; will block on I/O until time 1676ms [Q Y A C B Z Y X C]
time 1479ms: Process Y started using the CPU with 10ms remaining [Q A C B Z Y X C]
time 1489ms: Process Y completed a CPU burst; 3 bursts to go [Q A C B Z Y X C]
time 1489ms: Process Y switching out of CPU; will block on I/O until time 1692ms [Q A C B Z Y X C]
time 1495ms: Process A started using the CPU with 6ms remaining [Q C B Z Y X C]
time 1501ms: Process A completed a CPU burst; 3 bursts to go [Q C B Z Y X C]
time 1501ms: Process A switching out of CPU; will block on I/O until time 1704ms [Q C B Z Y X C]
time 1507ms: Process C started using the CPU with 8ms remaining [Q B Z Y X C]
time 1515ms: Process C completed a CPU burst; 3 bursts to go [Q B Z Y X C]
time 1515ms: Process C switching out of CPU; will block on I/O until time 1718ms [Q B Z Y X C]
time 1521ms: Process B started using the CPU with 7ms remaining [Q Z Y X C]
time 1528ms: Process B completed a CPU burst; 3 bursts to go [Q Z Y X C]
time 1528ms: Process B switching out of CPU; will block on I/O until time 1731ms [Q Z Y X C]
time 1534ms: Process Z started using the CPU with 11ms remaining [Q Y X C]
time 1545ms: Process Z completed a CPU burst; 3 bursts to go [Q Y X C]
time 1545ms: Process Z switching out of CPU; will block on I/O until time 1748ms [Q Y X C]
time 1551ms: Process Y started using the CPU with 10ms remaining [Q X C]
time 1561ms: Process Y completed a CPU burst; 3 bursts to go [Q X C]
time 1561ms: Process Y switching out of CPU; will block on I/O until time 1764ms [Q X C]
time 1567ms: Process X started using the CPU with 9ms remaining [Q C]
time 1576ms: Process X completed a CPU burst; 3 bursts to go [Q C]
time 1576ms: Process X switching out of CPU; will block on I/O until time 1779ms [Q C]
time 1582ms: Process C started using the CPU with 8ms remaining [Q <empty>]
time 1590ms: Process C completed a CPU burst; 3 bursts to go [Q <empty>]
time 1590ms: Process C switching out of CPU; will block on I/O until time 1793ms [Q <empty>]
time 1704ms: Process A completed I/O; added to ready queue [Q A]
time 1707ms: Process A started using the CPU [Q <empty>]
time 1731ms: Process B completed I/O; added to ready queue [Q B]
time 1748ms: Process Z completed I/O; added to ready queue [Q B Z]
time 1764ms: Process Y completed I/O; added to ready queue [Q B Z Y]
time 1779ms: Process X completed I/O; added to ready queue [Q B Z Y X]
time 1793ms: Process C completed I/O; added to ready queue [Q B Z Y X C]
time 1801ms: Time slice expired; process A preempted with 6ms to go [Q B Z Y X C]
time 1807ms: Process B started using the CPU [Q Z Y X C A]
time 1901ms: Time slice expired; process B preempted with 7ms to go [Q Z Y X C A]
time 1907ms: Process Z started using the CPU [Q Y X C A B]
time 2001ms: Time slice expired; process Z preempted with 11ms to go [Q Y X C A B]
time 2004ms: Process A completed I/O; added to ready queue [Q Y X C A B Z A]
time 2007ms: Process Y started using the CPU [Q X C A B Z A]
time 2101ms: Time slice expired; process Y preempted with 10ms to go [Q X C A B Z A]
time 2104ms: Process B completed I/O; added to ready queue [Q X C A B Z A Y B]
time 2107ms: Process X started using the CPU [Q C A B Z A Y B]
time 2201ms: Time slice expired; process X preempted with 9ms to go [Q C A B Z A Y B]
time 2204ms: Process Z completed I/O; added to ready queue [Q C A B Z A Y B X Z]
time 2207ms: Process C started using the CPU [Q A B Z A Y B X Z]
time 2301ms: Time slice expired; process C preempted with 8ms to go [Q A B Z A Y B X Z]
time 2304ms: Process Y completed I/O; added to ready queue [Q A B Z A Y B X Z C Y]
time 2307ms: Process A started using the CPU with 6ms remaining [Q B Z A Y B X Z C Y]
time 2313ms: Process A completed a CPU burst; 2 bursts to go [Q B Z A Y B X Z C Y]
time 2313ms: Process A switching out of CPU; will block on I/O until time 2516ms [Q B Z A Y B X Z C Y]
time 2319ms: Process B started using the CPU with 7ms remaining [Q Z A Y B X Z C Y]
time 2326ms: Process B completed a CPU burst; 2 bursts to go [Q Z A Y B X Z C Y]
time 2326ms: Process B switching out of CPU; will block on I/O until time 2529ms [Q Z A Y B X Z C Y]
time 2332ms: Process Z started using the CPU with 11ms remaining [Q A Y B X Z C Y]
time 2343ms: Process Z completed a CPU burst; 2 bursts to go [Q A Y B X Z C Y]
time 2343ms: Process Z switching out of CPU; will block on I/O until time 2546ms [Q A Y B X Z C Y]
time 2349ms: Process A started using the CPU with 6ms remaining [Q Y B X Z C Y]
time 2355ms: Process A completed a CPU burst; 2 bursts to go [Q Y B X Z C Y]
time 2355ms: Process A switching out of CPU; will block on I/O until time 2558ms [Q Y B X Z C Y]
time 2361ms: Process Y started using the CPU with 10ms remaining [Q B X Z C Y]
time 2371ms: Process Y completed a CPU burst; 2 bursts to go [Q B X Z C Y]
time 2371ms: Process Y switching out of CPU; will block on I/O until time 2574ms [Q B X Z C Y]
time 2377ms: Process B started using the CPU with 7ms remaining [Q X Z C Y]
time 2384ms: Process B completed a CPU burst; 2 bursts to go [Q X Z C Y]
time 2384ms: Process B switching out of CPU; will block on I/O until time 2587ms [Q X Z C Y]
time 2390ms: Process X started using the CPU with 9ms remaining [Q Z C Y]
time 2399ms: Process X completed a CPU burst; 2 bursts to go [Q Z C Y]
time 2399ms: Process X switching out of CPU; will block on I/O until time 2602ms [Q Z C Y]
time 2405ms: Process Z started using the CPU with 11ms remaining [Q C Y]
time 2416ms: Process Z completed a CPU burst; 2 bursts to go [Q C Y]
time 2416ms: Process Z switching out of CPU; will block on I/O until time 2619ms [Q C Y]
time 2422ms: Process C started using the CPU with 8ms remaining [Q Y]
time 2430ms: Process C completed a CPU burst; 2 bursts to go [Q Y]
time 2430ms: Process C switching out of CPU; will block on I/O until time 2633ms [Q Y]
time 2436ms: Process Y started using the CPU with 10ms remaining [Q <empty>]
time 2446ms: Process Y completed a CPU burst; 2 bursts to go [Q <empty>]
time 2446ms: Process Y switching out of CPU; will block on I/O until time 2649ms [Q <empty>]
time 2558ms: Process A completed I/O; added to ready queue [Q A]
time 2561ms: Process A started using the CPU [Q <empty>]
time 2587ms: Process B completed I/O; added to ready queue [Q B]
time 2602ms: Process X completed I/O; added to ready queue [Q B X]
time 2619ms: Process Z completed I/O; added to ready queue [Q B X Z]
time 2633ms: Process C completed I/O; added to ready queue [Q B X Z C]
time 2649ms: Process Y completed I/O; added to ready queue [Q B X Z C Y]
time 2655ms: Time slice expired; process A preempted with 6ms to go [Q B X Z C Y]
time 2661ms: Process B started using the CPU [Q X Z C Y A]
time 2755ms: Time slice expired; process B preempted with 7ms to go [Q X Z C Y A]
time 2761ms: Process X started using the CPU [Q Z C Y A B]
time 2855ms: Time slice expired; process X preempted with 9ms to go [Q Z C Y A B]
time 2858ms: Process A completed I/O; added to ready queue [Q Z C Y A B X A]
time 2861ms: Process Z started using the CPU [Q C Y A B X A]
time 2955ms: Time slice expired; process Z preempted with 11ms to go [Q C Y A B X A]
time 2958ms: Process B completed I/O; added to ready queue [Q C Y A B X A Z B]
time 2961ms: Process C started using the CPU [Q Y A B X A Z B]
time 3055ms: Time slice expired; process C preempted with 8ms to go [Q Y A B X A Z B]
time 3058ms: Process X completed I/O; added to ready queue [Q Y A B X A Z B C X]
time 3061ms: Process Y started using the CPU [Q A B X A Z B C X]
time 3155ms: Time slice expired; process Y preempted with 10ms to go [Q A B X A Z B C X]
time 3158ms: Process Z completed I/O; added to ready queue [Q A B X A Z B C X Y Z]
time 3161ms: Process A started using the CPU with 6ms remaining [Q B X A Z B C X Y Z]
time 3167ms: Process A completed a CPU burst; 1 burst to go [Q B X A Z B C X Y Z]
time 3167ms: Process A switching out of CPU; will block on I/O until time 3370ms [Q B X A Z B C X Y Z]
time 3173ms: Process B started using the CPU with 7ms remaining [Q X A Z B C X Y Z]
time 3180ms: Process B completed a CPU burst; 1 burst to go [Q X A Z B C X Y Z]
time 3180ms: Process B switching out of CPU; will block on I/O until time 3383ms [Q X A Z B C X Y Z]
time 3186ms: Process X started using the CPU with 9ms remaining [Q A Z B C X Y Z]
time 3195ms: Process X completed a CPU burst; 1 burst to go [Q A Z B C X Y Z]
time 3195ms: Process X switching out of CPU; will block on I/O until time 3398ms [Q A Z B C X Y Z]
time 3201ms: Process A started using the CPU with 6ms remaining [Q Z B C X Y Z]
time 3207ms: Process A completed a CPU burst; 1 burst to go [Q Z B C X Y Z]
time 3207ms: Process A switching out of CPU; will block on I/O until time 3410ms [Q Z B C X Y Z]
time 3213ms: Process Z started using the CPU with 11ms remaining [Q B C X Y Z]
time 3224ms: Process Z completed a CPU burst; 1 burst to go [Q B C X Y Z]
time 3224ms: Process Z switching out of CPU; will block on I/O until time 3427ms [Q B C X Y Z]
time 3230ms: Process B started using the CPU with 7ms remaining [Q C X Y Z]
time 3237ms: Process B completed a CPU burst; 1 burst to go [Q C X Y Z]
time 3237ms: Process B switching out of CPU; will block on I/O until time 3440ms [Q C X Y Z]
time 3243ms: Process C started using the CPU with 8ms remaining [Q X Y Z]
time 3251ms: Process C completed a CPU burst; 1 burst to go [Q X Y Z]
time 3251ms: Process C switching out of CPU; will block on I/O until time 3454ms [Q X Y Z]
time 3257ms: Process X started using the CPU with 9ms remaining [Q Y Z]
time 3266ms: Process X completed a CPU burst; 1 burst to go [Q Y Z]
time 3266ms: Process X switching out of CPU; will block on I/O until time 3469ms [Q Y Z]
time 3272ms: Process Y started using the CPU with 10ms remaining [Q Z]
time 3282ms: Process Y completed a CPU burst; 1 burst to go [Q Z]
time 3282ms: Process Y switching out of CPU; will block on I/O until time 3485ms [Q Z]
time 3288ms: Process Z started using the CPU with 11ms remaining [Q <empty>]
time 3299ms: Process Z completed a CPU burst; 1 burst to go [Q <empty>]
time 3299ms: Process Z switching out of CPU; will block on I/O until time 3502ms [Q <empty>]
time 3410ms: Process A completed I/O; added to ready queue [Q A]
time 3413ms: Process A started using the CPU [Q <empty>]
time 3440ms: Process B completed I/O; added to ready queue [Q B]
time 3454ms: Process C completed I/O; added to ready queue [Q B C]
time 3469ms: Process X completed I/O; added to ready queue [Q B C X]
time 3485ms: Process Y completed I/O; added to ready queue [Q B C X Y]
time 3502ms: Process Z completed I/O; added to ready queue [Q B C X Y Z]
time 3507ms: Time slice expired; process A preempted with 6ms to go [Q B C X Y Z]
time 3513ms: Process B started using the CPU [Q C X Y Z A]
time 3607ms: Time slice expired; process B preempted with 7ms to go [Q C X Y Z A]
time 3613ms: Process C started using the CPU [Q X Y Z A B]
time 3707ms: Time slice expired; process C preempted with 8ms to go [Q X Y Z A B]
time 3710ms: Process A completed I/O; added to ready queue [Q X Y Z A B C A]
time 3713ms: Process X started using the CPU [Q Y Z A B C A]
time 3807ms: Time slice expired; process X preempted with 9ms to go [Q Y Z A B C A]
time 3810ms: Process B completed I/O; added to ready queue [Q Y Z A B C A X B]
time 3813ms: Process Y started using the CPU [Q Z A B C A X B]
time 3907ms: Time slice expired; process Y preempted with 10ms to go [Q Z A B C A X B]
time 3910ms: Process C completed I/O; added to ready queue [Q Z A B C A X B Y C]
time 3913ms: Process Z started using the CPU [Q A B C A X B Y C]
time 4007ms: Time slice expired; process Z preempted with 11ms to go [Q A B C A X B Y C]
time 4010ms: Process X completed I/O; added to ready queue [Q A B C A X B Y C Z X]
time 4013ms: Process A started using the CPU with 6ms remaining [Q B C A X B Y C Z X]
time 4019ms: Process A terminated [Q B C A X B Y C Z X]
time 4025ms: Process B started using the CPU with 7ms remaining [Q C A X B Y C Z X]
time 4032ms: Process B terminated [Q C A X B Y C Z X]
time 4038ms: Process C started using the CPU with 8ms remaining [Q A X B Y C Z X]
time 4046ms: Process C terminated [Q A X B Y C Z X]
time 4052ms: Process A started using the CPU with 6ms remaining [Q X B Y C Z X]
time 4058ms: Process A terminated [Q X B Y C Z X]
time 4064ms: Process X started using the CPU with 9ms remaining [Q B Y C Z X]
time 4073ms: Process X terminated [Q B Y C Z X]
time 4079ms: Process B started using the CPU with 7ms remaining [Q Y C Z X]
time 4086ms: Process B terminated [Q Y C Z X]
time 4092ms: Process Y started using the CPU with 10ms remaining [Q C Z X]
time 4102ms: Process Y terminated [Q C Z X]
time 4108ms: Process C started using the CPU with 8ms remaining [Q Z X]
time 4116ms: Process C terminated [Q Z X]
time 4122ms: Process Z started using the CPU with 11ms remaining [Q X]
time 4133ms: Process Z terminated [Q X]
time 4136ms: Simulator ended for RR
